[2024-12-11 22:44:35,535] ERROR log_exception() L1449 Exception on /projeto [POST] - call_trace=C:\Users\prisc\AppData\Local\Programs\Python\Python311\Lib\site-packages\flask\app.py L1449
Traceback (most recent call last):
  File "C:\Users\prisc\OneDrive\Documentos\PosGraduacao\DesenvolvimentoFullStack\desenvolvimento-full-stack-main\desenvolvimento-full-stack-basico\mvp-portifolio-projetos\app-api\app.py", line 54, in criar_projeto
    projeto = Projeto(**body.dict())
            ^^^^^^^^^^^^^^^^^^^^^^
  File "<string>", line 4, in __init__
  File "C:\Users\prisc\AppData\Local\Programs\Python\Python311\Lib\site-packages\sqlalchemy\orm\state.py", line 481, in _initialize_instance
    with util.safe_reraise():
  File "C:\Users\prisc\AppData\Local\Programs\Python\Python311\Lib\site-packages\sqlalchemy\util\langhelpers.py", line 70, in __exit__
    compat.raise_(
  File "C:\Users\prisc\AppData\Local\Programs\Python\Python311\Lib\site-packages\sqlalchemy\util\compat.py", line 208, in raise_
    raise exception
  File "C:\Users\prisc\AppData\Local\Programs\Python\Python311\Lib\site-packages\sqlalchemy\orm\state.py", line 479, in _initialize_instance
    return manager.original_init(*mixed[1:], **kwargs)
           ^^^^^^^^^^^^^^^^^^^^^^^^^^^^^^^^^^^^^^^^^^^
  File "C:\Users\prisc\OneDrive\Documentos\PosGraduacao\DesenvolvimentoFullStack\desenvolvimento-full-stack-main\desenvolvimento-full-stack-basico\mvp-portifolio-projetos\app-api\model\projeto.py", line 58, in __init__
    self.validar_sigla()
  File "C:\Users\prisc\OneDrive\Documentos\PosGraduacao\DesenvolvimentoFullStack\desenvolvimento-full-stack-main\desenvolvimento-full-stack-basico\mvp-portifolio-projetos\app-api\model\projeto.py", line 80, in validar_sigla
    raise ValueError("A sigla do projeto deve conter apenas letras maiúsculas e números.")
ValueError: A sigla do projeto deve conter apenas letras maiúsculas e números.

During handling of the above exception, another exception occurred:

Traceback (most recent call last):
  File "C:\Users\prisc\AppData\Local\Programs\Python\Python311\Lib\site-packages\flask\app.py", line 2073, in wsgi_app
    response = self.full_dispatch_request()
               ^^^^^^^^^^^^^^^^^^^^^^^^^^^^
  File "C:\Users\prisc\AppData\Local\Programs\Python\Python311\Lib\site-packages\flask\app.py", line 1519, in full_dispatch_request
    rv = self.handle_user_exception(e)
         ^^^^^^^^^^^^^^^^^^^^^^^^^^^^^
  File "C:\Users\prisc\AppData\Local\Programs\Python\Python311\Lib\site-packages\flask_cors\extension.py", line 165, in wrapped_function
    return cors_after_request(app.make_response(f(*args, **kwargs)))
                                                ^^^^^^^^^^^^^^^^^^
  File "C:\Users\prisc\AppData\Local\Programs\Python\Python311\Lib\site-packages\flask\app.py", line 1517, in full_dispatch_request
    rv = self.dispatch_request()
         ^^^^^^^^^^^^^^^^^^^^^^^
  File "C:\Users\prisc\AppData\Local\Programs\Python\Python311\Lib\site-packages\flask\app.py", line 1503, in dispatch_request
    return self.ensure_sync(self.view_functions[rule.endpoint])(**req.view_args)
           ^^^^^^^^^^^^^^^^^^^^^^^^^^^^^^^^^^^^^^^^^^^^^^^^^^^^^^^^^^^^^^^^^^^^^
  File "C:\Users\prisc\AppData\Local\Programs\Python\Python311\Lib\site-packages\flask_openapi3\scaffold.py", line 191, in wrapper
    resp = _do_wrapper(
           ^^^^^^^^^^^^
  File "C:\Users\prisc\AppData\Local\Programs\Python\Python311\Lib\site-packages\flask_openapi3\do_wrapper.py", line 135, in _do_wrapper
    response = func(**request_kwargs)
               ^^^^^^^^^^^^^^^^^^^^^^
  File "C:\Users\prisc\OneDrive\Documentos\PosGraduacao\DesenvolvimentoFullStack\desenvolvimento-full-stack-main\desenvolvimento-full-stack-basico\mvp-portifolio-projetos\app-api\app.py", line 70, in criar_projeto
    session.rollback()
    ^^^^^^^
UnboundLocalError: cannot access local variable 'session' where it is not associated with a value
[2024-12-11 22:44:35,583] INFO _log() L225  127.0.0.1 - - [11/Dec/2024 22:44:35] "[35m[1mPOST /projeto HTTP/1.1[0m" 500 - - call_trace=C:\Users\prisc\AppData\Local\Programs\Python\Python311\Lib\site-packages\werkzeug\_internal.py L225 
[2024-12-11 22:47:14,667] WARNING _log() L225   * Running on all addresses.
   WARNING: This is a development server. Do not use it in a production deployment. - call_trace=C:\Users\prisc\AppData\Local\Programs\Python\Python311\Lib\site-packages\werkzeug\_internal.py L225 
[2024-12-11 22:47:14,667] INFO _log() L225   * Running on http://192.168.3.46:5000/ (Press CTRL+C to quit) - call_trace=C:\Users\prisc\AppData\Local\Programs\Python\Python311\Lib\site-packages\werkzeug\_internal.py L225 
[2024-12-11 22:47:23,247] INFO listar_projetos() L83   Listagem de projetos realizada com sucesso. - call_trace=C:\Users\prisc\OneDrive\Documentos\PosGraduacao\DesenvolvimentoFullStack\desenvolvimento-full-stack-main\desenvolvimento-full-stack-basico\mvp-portifolio-projetos\app-api\app.py L83  
[2024-12-11 22:47:23,249] INFO listar_projetos() L88   4Projetos encontrado: - call_trace=C:\Users\prisc\OneDrive\Documentos\PosGraduacao\DesenvolvimentoFullStack\desenvolvimento-full-stack-main\desenvolvimento-full-stack-basico\mvp-portifolio-projetos\app-api\app.py L88  
[2024-12-11 22:47:23,256] INFO _log() L225  127.0.0.1 - - [11/Dec/2024 22:47:23] "GET /projetos HTTP/1.1" 200 - - call_trace=C:\Users\prisc\AppData\Local\Programs\Python\Python311\Lib\site-packages\werkzeug\_internal.py L225 
[2024-12-11 22:47:49,480] ERROR log_exception() L1449 Exception on /projeto [POST] - call_trace=C:\Users\prisc\AppData\Local\Programs\Python\Python311\Lib\site-packages\flask\app.py L1449
Traceback (most recent call last):
  File "C:\Users\prisc\OneDrive\Documentos\PosGraduacao\DesenvolvimentoFullStack\desenvolvimento-full-stack-main\desenvolvimento-full-stack-basico\mvp-portifolio-projetos\app-api\app.py", line 54, in criar_projeto
    projeto = Projeto(**body.dict())
            ^^^^^^^^^^^^^^^^^^^^^^
  File "<string>", line 4, in __init__
  File "C:\Users\prisc\AppData\Local\Programs\Python\Python311\Lib\site-packages\sqlalchemy\orm\state.py", line 481, in _initialize_instance
    with util.safe_reraise():
  File "C:\Users\prisc\AppData\Local\Programs\Python\Python311\Lib\site-packages\sqlalchemy\util\langhelpers.py", line 70, in __exit__
    compat.raise_(
  File "C:\Users\prisc\AppData\Local\Programs\Python\Python311\Lib\site-packages\sqlalchemy\util\compat.py", line 208, in raise_
    raise exception
  File "C:\Users\prisc\AppData\Local\Programs\Python\Python311\Lib\site-packages\sqlalchemy\orm\state.py", line 479, in _initialize_instance
    return manager.original_init(*mixed[1:], **kwargs)
           ^^^^^^^^^^^^^^^^^^^^^^^^^^^^^^^^^^^^^^^^^^^
  File "C:\Users\prisc\OneDrive\Documentos\PosGraduacao\DesenvolvimentoFullStack\desenvolvimento-full-stack-main\desenvolvimento-full-stack-basico\mvp-portifolio-projetos\app-api\model\projeto.py", line 59, in __init__
    self.validar_custo()
  File "C:\Users\prisc\OneDrive\Documentos\PosGraduacao\DesenvolvimentoFullStack\desenvolvimento-full-stack-main\desenvolvimento-full-stack-basico\mvp-portifolio-projetos\app-api\model\projeto.py", line 87, in validar_custo
    if self.custo <= 0:
       ^^^^^^^^^^^^^^^
TypeError: '<=' not supported between instances of 'str' and 'int'

During handling of the above exception, another exception occurred:

Traceback (most recent call last):
  File "C:\Users\prisc\AppData\Local\Programs\Python\Python311\Lib\site-packages\flask\app.py", line 2073, in wsgi_app
    response = self.full_dispatch_request()
               ^^^^^^^^^^^^^^^^^^^^^^^^^^^^
  File "C:\Users\prisc\AppData\Local\Programs\Python\Python311\Lib\site-packages\flask\app.py", line 1519, in full_dispatch_request
    rv = self.handle_user_exception(e)
         ^^^^^^^^^^^^^^^^^^^^^^^^^^^^^
  File "C:\Users\prisc\AppData\Local\Programs\Python\Python311\Lib\site-packages\flask_cors\extension.py", line 165, in wrapped_function
    return cors_after_request(app.make_response(f(*args, **kwargs)))
                                                ^^^^^^^^^^^^^^^^^^
  File "C:\Users\prisc\AppData\Local\Programs\Python\Python311\Lib\site-packages\flask\app.py", line 1517, in full_dispatch_request
    rv = self.dispatch_request()
         ^^^^^^^^^^^^^^^^^^^^^^^
  File "C:\Users\prisc\AppData\Local\Programs\Python\Python311\Lib\site-packages\flask\app.py", line 1503, in dispatch_request
    return self.ensure_sync(self.view_functions[rule.endpoint])(**req.view_args)
           ^^^^^^^^^^^^^^^^^^^^^^^^^^^^^^^^^^^^^^^^^^^^^^^^^^^^^^^^^^^^^^^^^^^^^
  File "C:\Users\prisc\AppData\Local\Programs\Python\Python311\Lib\site-packages\flask_openapi3\scaffold.py", line 191, in wrapper
    resp = _do_wrapper(
           ^^^^^^^^^^^^
  File "C:\Users\prisc\AppData\Local\Programs\Python\Python311\Lib\site-packages\flask_openapi3\do_wrapper.py", line 135, in _do_wrapper
    response = func(**request_kwargs)
               ^^^^^^^^^^^^^^^^^^^^^^
  File "C:\Users\prisc\OneDrive\Documentos\PosGraduacao\DesenvolvimentoFullStack\desenvolvimento-full-stack-main\desenvolvimento-full-stack-basico\mvp-portifolio-projetos\app-api\app.py", line 70, in criar_projeto
    session.rollback()
    ^^^^^^^
UnboundLocalError: cannot access local variable 'session' where it is not associated with a value
[2024-12-11 22:47:49,482] INFO _log() L225  127.0.0.1 - - [11/Dec/2024 22:47:49] "OPTIONS /projeto HTTP/1.1" 200 - - call_trace=C:\Users\prisc\AppData\Local\Programs\Python\Python311\Lib\site-packages\werkzeug\_internal.py L225 
[2024-12-11 22:47:49,495] INFO _log() L225  127.0.0.1 - - [11/Dec/2024 22:47:49] "[35m[1mPOST /projeto HTTP/1.1[0m" 500 - - call_trace=C:\Users\prisc\AppData\Local\Programs\Python\Python311\Lib\site-packages\werkzeug\_internal.py L225 
